<?xml version="1.0"?>
<robot xmlns:xacro="http://www.ros.org/wiki/xacro">
  <!--
    wheel.urdf.xacro
    Defines a Xacro macro 'wheel_with_suspension' for suspension+wheel assembly.
    Params:
      number           : integer index (1..8)
      parent           : parent link name (e.g., base_link)
      suspension_xyz   : "x y z" for prismatic joint origin
      wheel_xyz        : "x y z" for continuous joint origin
  -->
  <xacro:macro name="wheel_with_suspension" params="number parent suspension_xyz wheel_xyz">
    <!-- Suspension Link -->
    <link name="Suspension_${number}">
      <inertial>
        <origin xyz="0 0 0" rpy="0 0 0"/>
        <mass value="10.0"/>
        <inertia ixx="5.0" ixy="0.0" ixz="0.0"
                 iyy="5.0" iyz="0.0" izz="5.0"/>
      </inertial>
      <visual>
        <origin xyz="0 0 0" rpy="0 0 0"/>
        <geometry>
          <mesh filename="package://j8_xacro_model/meshes/Suspension_${number}.STL"/>
        </geometry>
      </visual>
      <collision>
        <origin xyz="0 0 0" rpy="0 0 0"/>
        <geometry>
          <mesh filename="package://j8_xacro_model/meshes/Suspension_${number}.STL"/>
        </geometry>
      </collision>
    </link>

    <!-- Prismatic Joint (parent -> suspension) -->
    <joint name="base_Suspension_${number}_joint" type="prismatic">
      <origin xyz="${suspension_xyz}" rpy="0 0 0"/>
      <parent link="${parent}"/>
      <child  link="Suspension_${number}"/>
      <axis  xyz="0 0 1"/>
      <limit effort="1e12" lower="-0.10" upper="0.10" velocity="0.0"/>
      <dynamics damping="100.0" friction="0.0"/>
    </joint>

    <!-- Wheel Link -->
    <link name="Wheel_${number}">
      <inertial>
        <origin xyz="0 0 0" rpy="0 0 0"/>
        <mass value="5.205"/>
        <inertia ixx="3.663" ixy="0.0" ixz="0.0"
                 iyy="3.663" iyz="0.0" izz="5.435"/>
      </inertial>
      <visual>
        <origin xyz="0 0 0" rpy="1.5708 0 0"/>
        <geometry>
          <cylinder length="0.30" radius="0.298"/>
        </geometry>
        <geometry>
          <mesh filename="package://j8_xacro_model/meshes/Wheel${number}.STL"/>
        </geometry>
      </visual>
      <collision>
        <origin xyz="0 0 0" rpy="1.5708 0 0"/>
        <geometry>
          <cylinder length="0.30" radius="0.298"/>
        </geometry>
      </collision>
    </link>

    <!-- Continuous Joint (suspension -> wheel) -->
    <joint name="Suspension_${number}_Wheel_${number}_joint" type="continuous">
      <origin xyz="${wheel_xyz}" rpy="0 0 0"/>
      <parent link="Suspension_${number}"/>
      <child  link="Wheel_${number}"/>
      <axis  xyz="0 1 0"/>
    </joint>
  </xacro:macro>
</robot>
